Workbook

Sheet REPORTE
B2: REPORTE DE ESTATUS SEMANAL
E5: PROYECTO: | H5: ALTOZANO - ZORRO - 6 VIVIENDAS | L5: SEMANA No.
E6: UBICACIÓN: | H6: HERMOSILLO, SONORA | L6: 11
E7: GERENCIA DE PROYECTO | H7: METTA GROUP
E8: FECHA DEL PERIODO: | H8: SEMANA 11 - DEL 20 AL 25 DE JULIO DEL 2026
B10: ACTIVIDADES
B11: ACTIVIDADES REALIZADAS ESTA SEMANA - 11 | H11: ACTIVIDADES PROGRAMADAS PROXIMA SEMANA - 12
B12: No. Lote | C12: TAREA | H12: No. Lote | I12: TAREA
B13: L02 | C13: Se continuó con muros de tabique y block hasta cerramientos | H13: L02 | I13: Inicio de colados de cerramiento
B14: L03 | C14: Se continuó con muros de tabique y block hasta cerramientos | H14: L03 | I14: Inicio de colados de cerramiento
B15: L04 | C15: Se retomó armado de trabes en losa de entrepiso | H15: L04 | I15: Instalaciones eléctricas en losa de entrepiso
B16: L21 | C16: Terminación de instalaciones Hidrosanitarias | H16: L04 | I16: Instalaciones Hidro-Sanitarias en losa de entrepiso
B17: L21 | C17: Fumigación de terreno | H17: L22 | I17: Inicio de muros de tabique
B18: L21 | C18: Inicio de colocación de hule negro | H18: L22 | I18: Colado de losa de cimentación
B19: L20 | C19: Terminación de instalaciones Hidrosanitarias | H19: L21 | I19: Colocación de cimbra perimetral
H20: L21 | I20: Colocación de acero en sitio
H21: L21 | I21: Colado de losa de cimentación
H22: L20 | I22: Terminación de instalaciones hidro-sanitarias
H23: L20 | I23: Fumigación y colocación de acero en sitio
H24: L20 | I24: Colado de losa de cimentación
B29: PROBLEMAS QUE PUEDEN VOLVERSE CRÍTICOS | H29: ESTATUS | J29: FECHA LÍMITE | L29: RESPONSABLE
B38: CONCEPTO | G38: PROGRAM. | H38: REAL | I38: VARIACION | J38: PROGRAMADO VS REAL
B40: CASAS ZORRO - ALTOZANO RESIDENCIAL
B41: 6 CASAS
B42: =+AVANCES!B6 -> LOTE 04 M-661 ARTICO-A | G42: =+AVANCES!E6 -> 0.32157768 | H42: =+AVANCES!F6 -> 0.19731815 | I42: =+H42-G42 -> -0.12425952
B43: =+AVANCES!B260 -> LOTE 02 M-661 CORSAC-B | G43: =+AVANCES!E260 -> 0.22980963 | H43: =+AVANCES!F260 -> 0.13764696 | I43: =+H43-G43 -> -0.092162668
B44: =+AVANCES!B560 -> LOTE 03 M-661 CORSAC-A | G44: =+AVANCES!E560 -> 0.21252809 | H44: =+AVANCES!F560 -> 0.13824485 | I44: =+H44-G44 -> -0.074283241
B45: =+AVANCES!B860 -> LOTE 22 M-663 CORSAC-B | G45: =+AVANCES!E860 -> 0.1092572 | H45: =+AVANCES!F860 -> 0.088439239 | I45: =+H45-G45 -> -0.020817964
B46: =+AVANCES!B1160 -> LOTE 21 M-663 CORSAC-A | G46: =+AVANCES!E1160 -> 0.079901913 | H46: =+AVANCES!F1160 -> 0.06143797 | I46: =+H46-G46 -> -0.018463943
B47: =+AVANCES!B1460 -> LOTE 20 M-663 ARTICO-A | G47: =+AVANCES!E1460 -> 0.042489367 | H47: =+AVANCES!F1460 -> 0.017571063 | I47: =+H47-G47 -> -0.024918304
B50: LÍNEA DEL TIEMPO GENERAL
B58: REPORTE DE ESTATUS SEMANAL
E61: PROYECTO: | H61: ALTOZANO - ZORRO - 6 VIVIENDAS | L61: SEMANA No.
E62: UBICACIÓN: | H62: HERMOSILLO, SONORA | L62: 11
E63: GERENCIA DE PROYECTO | H63: METTA GROUP
E64: FECHA DEL PERIODO: | H64: SEMANA 11 - DEL 20 AL 25 DE JULIO DEL 2026
B66: PROGRAMA MAESTRO
C93: AVANCE PROGRAMADO SEMANA - 11 | G93: AVANCE FÍSICO - FINANCIERO SEMANA - 11 | K93: VARIACION
C94: =+'CURVA S BASE'!M7 -> 2192434.7 | G94: =+AVANCES!H4 -> 1406797.5 | K94: =+G94-C94 -> -785637.22
C95: =+C94/'CURVA S BASE'!B16 -> 0.16839856 | G95: =+AVANCES!F4 -> 0.10670393 | K95: =+G95-C95 -> -0.061694636
...

Sheet AVANCES
E2: % PROGRAMADO | F2: % REAL | G2: $ PROGRAMADO | H2: $ REAL
B4: TOTAL 6 CASAS | C4: =+C1460+C1160+C860+C260+C560+C6 -> 13184121 | E4: =+G4/C4 -> 0.16418117 | F4: =+H4/C4 -> 0.10670393 | G4: =+G1460+G1160+G860+G260+G560+G6 -> 2164584.3 | H4: =+H1460+H1160+H860+H260+H560+H6 -> 1406797.5 | J4: =+H4-G4 -> -757786.87 | K4: =+F4-E4 -> -0.057477239
B6: LOTE 04 M-661 ARTICO-A | C6: =+C7+C9+C12+C39+C54+C56+C82+C94+C109+C117+C120+C123+C142+C147+C154+C169+C171+C174+C181+C186+C204+C230+C233+C242+C249+C253+C257 -> 1720903.2 | E6: =+G6/C6 -> 0.32157768 | F6: =+H6/C6 -> 0.19731815 | G6: =+G7+G9+G12+G39+G54+G56+G82+G204+G230 -> 553404.06 | H6: =+H7+H9+H12+H39+H54+H56+H82+H204+H230 -> 339565.44 | J6: =+F6-E6 -> -0.12425952
B7: TRABAJOS PRELIMINARES | C7: 2101.94 | E7: =+G7/C7 -> 1 | F7: =+H7/C7 -> 1 | G7: =+G8 -> 2101.94 | H7: =+H8 -> 2101.94 | J7: =+F7-E7 -> 0
B8: Trazo y nivelación | C8: 2101.94 | E8: 1 | F8: 1 | G8: =+E8*C8 -> 2101.94 | H8: =+F8*C8 -> 2101.94 | J8: =+F8-E8 -> 0
B9: EXCAVACIONES | C9: 3471.96 | E9: =+G9/C9 -> 1 | F9: =+H9/C9 -> 1 | G9: =+G10+G11 -> 3471.96 | H9: =+H10+H11 -> 3471.96 | J9: =+F9-E9 -> 0
B10: Excavación a mano material tipo B | C10: 3471.96 | E10: 1 | F10: 1 | G10: =+E10*C10 -> 3471.96 | H10: =+F10*C10 -> 3471.96 | J10: =+F10-E10 -> 0
B11: Acarreo en carretilla 20 m | C11: 0 | E11: 1 | F11: 1 | G11: 0 | H11: =+F11*C11 -> 0 | J11: =+F11-E11 -> 0
B12: CIMENTACION | C12: 114357.79 | E12: =+G12/C12 -> 1 | F12: =+H12/C12 -> 1 | G12: =SUM(G13:G38) -> 114357.79 | H12: =SUM(H13:H38) -> 114357.79 | J12: =+F12-E12 -> 0
B13: Cimbra perimetral losa de cimentación | C13: 7809.03 | E13: 1 | F13: 1 | G13: =+E13*C13 -> 7809.03 | H13: =+F13*C13 -> 7809.03 | J13: =+F13-E13 -> 0
B14: Sistema antitermitas PVC | C14: 5045.08 | E14: 1 | F14: 1 | G14: =+E14*C14 -> 5045.08 | H14: =+F14*C14 -> 5045.08 | J14: =+F14-E14 -> 0
B15: Hule negro en cimentación | C15: 2143.32 | E15: 1 | F15: 1 | G15: =+E15*C15 -> 2143.32 | H15: =+F15*C15 -> 2143.32 | J15: =+F15-E15 -> 0
B16: Ramaleo poliducto eléctrico cimentación | C16: 2764.5 | E16: 1 | F16: 1 | G16: =+E16*C16 -> 2764.5 | H16: =+F16*C16 -> 2764.5 | J16: =+F16-E16 -> 0
B17: Ramaleo eléctrico base-medición a centro de carga | C17: 1573.13 | E17: 1 | F17: 1 | G17: =+E17*C17 -> 1573.13 | H17: =+F17*C17 -> 1573.13 | J17: =+F17-E17 -> 0
B18: Ramaleo eléctrico exterior | C18: 549.68 | E18: 1 | F18: 1 | G18: =+E18*C18 -> 549.68 | H18: =+F18*C18 -> 549.68 | J18: =+F18-E18 -> 0
B19: Ramaleo para cable poliducto 3/4 | C19: 1205.12 | E19: 1 | F19: 1 | G19: =+E19*C19 -> 1205.12 | H19: =+F19*C19 -> 1205.12 | J19: =+F19-E19 -> 0
B20: Ramaleo para TV poliducto 3/4 | C20: 903.84 | E20: 1 | F20: 1 | G20: =+E20*C20 -> 903.84 | H20: =+F20*C20 -> 903.84 | J20: =+F20-E20 -> 0
B21: Ramaleo hidráulico CPVC 1 cimentación | C21: 1475.2 | E21: 1 | F21: 1 | G21: =+E21*C21 -> 1475.2 | H21: =+F21*C21 -> 1475.2 | J21: =+F21-E21 -> 0
B22: Ramaleo hidráulico CPVC 3/4 cimentación | C22: 2857.22 | E22: 1 | F22: 1 | G22: =+E22*C22 -> 2857.22 | H22: =+F22*C22 -> 2857.22 | J22: =+F22-E22 -> 0
B23: Ramaleo hidráulico CPVC 1/2 cimentación | C23: 2531.74 | E23: 1 | F23: 1 | G23: =+E23*C23 -> 2531.74 | H23: =+F23*C23 -> 2531.74 | J23: =+F23-E23 -> 0
B24: Prueba hidráulica | C24: 574.99 | E24: 1 | F24: 1 | G24: =+E24*C24 -> 574.99 | H24: =+F24*C24 -> 574.99 | J24: =+F24-E24 -> 0
... B38: Cimbra frontera zapatas | C38: 3005.4 | E38: 1 | F38: 1 | G38: =+E38*C38 -> 3005.4 | H38: =+F38*C38 -> 3005.4 | J38: =+F38-E38 -> 0
B39: MUROS, PLANTA BAJA. CASTILLOS Y CERRAMIENTOS | C39: 142526.66 | E39: =+G39/C39 -> 1 | F39: =+H39/C39 -> 1 | G39: =SUM(G40:G53) -> 142526.66 | H39: =SUM(H40:H53) -> 142526.66 | J39: =+F39-E39 -> 0
B40: Anclaje de castillos y Columnas PB | C40: 0 | E40: 1 | F40: 1 | G40: =+E40*C40 -> 0 | H40: =+F40*C40 -> 0
B41: Castillo K1 | C41: 0 | E41: 1 | F41: 1 | G41: =+E41*C41 -> 0 | H41: =+F41*C41 -> 0
B42: Castillo K2 | C42: 6659.71 | E42: 1 | F42: 1 | G42: =+E42*C42 -> 6659.71 | H42: =+F42*C42 -> 6659.71
B43: Castillo K3 | C43: 1630.51 | E43: 1 | F43: 1 | G43: =+E43*C43 -> 1630.51 | H43: =+F43*C43 -> 1630.51
B44: Castillo K4 | C44: 28258.41 | E44: 1 | F44: 1 | G44: =+E44*C44 -> 28258.41 | H44: =+F44*C44 -> 28258.41
B45: Castillo K5 | C45: 6623.16 | E45: 1 | F45: 1 | G45: =+E45*C45 -> 6623.16 | H45: =+F45*C45 -> 6623.16
B46: Refuerzo de muro K6 | C46: 8627.4 | E46: 1 | F46: 1 | G46: =+E46*C46 -> 8627.4 | H46: =+F46*C46 -> 8627.4
B47: Columna C1 | C47: 4759.74 | E47: 1 | F47: 1 | G47: =+E47*C47 -> 4759.74 | H47: =+F47*C47 -> 4759.74
B48: Columna C2 | C48: 1930.42 | E48: 1 | F48: 1 | G48: =+E48*C48 -> 1930.42 | H48: =+F48*C48 -> 1930.42
B49: Dala de cerramiento CR-1 | C49: 15378.5 | E49: 1 | F49: 1 | G49: =+E49*C49 -> 15378.5 | H49: =+F49*C49 -> 15378.5
B50: Dala de cerramiento CR-2 | C50: 0 | E50: 1 | F50: 1 | G50: =+E50*C50 -> 0 | H50: =+F50*C50 -> 0
B51: Cadena block dala | C51: 12036.42 | E51: 1 | F51: 1 | G51: =+E51*C51 -> 12036.42 | H51: =+F51*C51 -> 12036.42
... B53: Muro de block planta baja | C53: 13340.85 | E53: 1 | F53: 1 | G53: =+E53*C53 -> 13340.85 | H53: =+F53*C53 -> 13340.85
B54: ESCALERA | C54: 19320.24 | E54: =+G54/C54 -> 0.99 | F54: 0.55 | G54: =+G55 -> 19127.038 | H54: =+H55 -> 9660.12
B55: Escalera de concreto armado | C55: 19320.24 | E55: 0.99 | F55: 0.5 | G55: =+E55*C55 -> 19127.038 | H55: =+F55*C55 -> 9660.12
B56: LOSA DE ENTREPISO | C56: 118803.13 | E56: =+G56/C56 -> 1 | F56: =+H56/C56 -> 0.40728336 | G56: =SUM(G57:G81) -> 118803.13 | H56: =SUM(H57:H81) -> 48386.538 | J56: =+F56-E56 -> -0.59271664
B57: Vigueta pretensada 1.40 m | C57: 706.06 | E57: 1 | F57: 1 | G57: =+E57*C57 -> 706.06 | H57: =+F57*C57 -> 706.06
...

Sheet CURVA S BASE
B1: INICIO | C1: SEM 1 | D1: SEM 2 | E1: SEM 3 | F1: SEM 4 | G1: SEM 5 | H1: SEM 6 | I1: SEM 7 | J1: SEM 8 | K1: SEM 9 | L1: SEM 10 | M1: SEM 11 | N1: SEM 12 | O1: SEM 13 | P1: SEM 14 | Q1: SEM 15 | R1: SEM 16 | S1: SEM 17 | T1: SEM 18 | U1: SEM 19 | V1: SEM 20 | W1: SEM 21 | X1: SEM 22 | Y1: SEM 23 | Z1: SEM 24 | AA1: SEM 25 | AB1: SEM 26 | AC1: SEM 27 | AD1: SEM 28 | AE1: SEM 29 | AF1: SEM 30 | AG1: SEM 31 | AH1: SEM 32 | AI1: SEM 33 | AJ1: SEM 34 | AK1: SEM 35 | AL1: SEM 36 | AM1: SEM 37 | AN1: SEM 38
A3: SEMANAL PROGRAMADO | B3: 0 | C3: 8251.84 | D3: 56591.48 | E3: 137533.68 | F3: 286436.26 | G3: 426067.55 | H3: 432997.32 | I3: 399305.8 | J3: 287655.57 | K3: 392489.59 | L3: 482050.72 | M3: 468189.67 | N3: 490891.73 | O3: 383096.34 | P3: 370147.27 | Q3: 268616.69 | R3: 274156.2 | S3: 206972.4 | T3: 223017.83 | U3: 266052.14 | V3: 506264.07 | W3: 736580.85 | X3: 826605.45 | Y3: 702657.14 | Z3: 652900.8 | AA3: 853117.7 | AB3: 816662.6 | AC3: 599730.56 | AD3: 517153.01 | AE3: 440851.67 | AF3: 274534.35 | AG3: 156240.02 | AH3: 115714.52 | AI3: 73347.4 | AJ3: 37913.3 | AK3: 10692.22 | AL3: 2635.18
A4: LINEA BASE - ORIGINAL | B4: 0 | C4: 8251.84 | D4: 64843.32 | E4: 144676.04 | F4: 245626.28 | G4: 415713.2 | H4: 682496.8 | I4: 1203996.9 | J4: =1491652.52+61097.17 -> 1552749.7 | K4: =1884142.11+61097.17 -> 1945239.3 | L4: 2366192.8 | M4: 2834382.5 | N4: 3325274.2 | O4: 3708370.6 | P4: 4078517.8 | Q4: 4347134.5 | R4: 4621290.7 | S4: 4828263.1 | T4: 5101281 | U4: 5667333.1 | V4: 6173597.2 | W4: 6910178 | X4: 7736783.5 | Y4: 8439440.6 | Z4: 9092341.4 | AA4: 9945459.1 | AB4: 10762122 | AC4: 11361852 | AD4: 11879005 | AE4: 12319857 | AF4: 12594391 | AG4: 12750631 | AH4: 12866346 | AI4: 12939693 | AJ4: 12977607 | AK4: 12988299 | AL4: 13019319
A6: SEMANAL PROGRAMADO | B6: 0 | C6: 8251.84 | D6: 56591.48 | E6: 137533.68 | F6: 286436.26 | G6: 426067.55 | H6: 432997.32 | I6: 399305.8 | J6: 287655.57 | K6: 392489.59 | L6: 482050.72 | M6: 468189.67 | N6: 490891.73 | O6: 383096.34 | P6: 370147.27 | Q6: 268616.69 | R6: =274156.2+103094.22 -> 377250.42 | S6: =206972.4+103094.22 -> 310066.62 | T6: =223017.83+103094.22+108871.45+133155.63 -> 568139.13 | U6: =266052.14+103094.22+108871.2 -> 478017.56 | V6: =506264.07+108871.2 -> 615135.27 | W6: =736580.85-28995.61 -> 707585.24 | X6: 826605.45 | Y6: 702657.14 | Z6: 652900.8 | AA6: 853117.7 | AB6: 816662.6 | AC6: 599730.56 | AD6: 517153.01 | AE6: 440851.67 | AF6: 274534.35 | AG6: 156240.02 | AH6: 115714.52 | AI6: 73347.4 | AJ6: =37913.3 -> 37913.3 | AK6: =10692.22 -> 10692.22 | AL6: =2635.18+0.5 -> 2635.68
A7: REPROGRAMACIÓN 01 ACUMULADO PROGRAMADO | B7: 0 | C7: 8251.84 | D7: 64843.32 | E7: 144676.04 | F7: 245626.28 | G7: 415713.2 | H7: 549341.17 | I7: 739231.17 | J7: 1026886.7 | K7: 1372458 | L7: 1724245 | M7: 2192434.7 | N7: 2683326.4 | O7: 3113340.7 | P7: 3483488 | Q7: 3752104.7 | R7: 4129355.1 | S7: 4439421.7 | T7: 5007560.9 | U7: 5615842.5 | V7: 6230977.7 | W7: 6938563 | X7: 7765168.4 | Y7: 8467825.6 | Z7: 9120726.4 | AA7: 9973844.1 | AB7: 10790507 | AC7: 11390237 | AD7: 11907390 | AE7: 12348242 | AF7: 12622776 | AG7: 12779016 | AH7: 12894731 | AI7: 12968078 | AJ7: 13005992 | AK7: 13016684 | AL7: 13019319
AL9: =+AL4-AL7 -> 0.003200002
A10: SEMANAL REAL | B10: 0 | C10: =+C11-B11 -> 18548.615 | D10: =+D11-C11 -> 37030.511 | E10: =+E11-D11 -> 108638.17 | F10: =+F11-E11 -> 85790.109 | G10: =+G11-F11 -> 168397.36 | H10: =+H11-G11 -> 130936.41 | I10: =+I11-H11 -> 175033.32 | J10: =+J11-I11 -> 85320.92 | ... M10: =+M11-L11 -> 152335.3
A11: ACUMULADO REAL | B11: 0 | C11: 18548.615 | D11: 55579.126 | E11: 164217.29 | F11: 250007.4 | G11: 418404.76 | H11: 549341.17 | I11: 724374.5 | J11: 809695.42 | K11: 1061482.4 | L11: 1254462.2 | M11: =+AVANCES!H4 -> 1406797.5 | AL11: 130264.04
C13: =+C11-C7 -> 10296.775 | D13: =+D11-D7 -> -9264.194 | E13: =+E11-E7 -> 19541.253 | F13: =+F11-F7 -> 4381.12 | G13: =+G11-G7 -> 2691.5599 | H13: =+H11-H7 -> 0 | I13: =+I11-I7 -> -14856.674 | J13: =+J11-J7 -> -217191.32
I15: =+I11-I4 -> -479622.45 | J15: =+J11-J4 -> -743054.27
A16: TOTAL | B16: =+AL4 -> 13019319
K18: 1419376.3
K19: =+K18-K7 -> 46918.303

Sheet Hoja1
D5: ALTOZANO - METTA - 6 CASAS | E5: 199d | F5: 46153 | G5: 1/20/27 12:00 | I5: ALTOZANO - METTA - 6 CASAS | J5: 199 días | K5: lun 5/11/26 | L5: mié 1/20/27
D6: HITOS IMPORTANTES | E6: 25d | F6: 46331.333 | G6: 46301.5 | I6: HITOS IMPORTANTES | J6: 25 días | K6: lun 5/11/26 | L6: mié 6/10/26
D7: LOTE 04 M-661 ARTICO-A | E7: 175d | F7: 46331.333 | G7: 12/16/26 2:00 | I7: LOTE 04 M-661 ARTICO-A | J7: 180 días | K7: lun 5/11/26 | L7: mar 12/22/26
D8: LOTE 02 M-661 CORSAC-B | E8: 178d | F8: 5/20/26 11:00 | G8: 46478.125 | I8: LOTE 02 M-661 CORSAC-B | J8: 178 días | K8: mié 5/20/26 | L8: lun 1/4/27
D9: LOTE 03 M-661 CORSAC-A | E9: 178d | F9: 5/20/26 11:00 | G9: 46478.125 | I9: LOTE 03 M-661 CORSAC-A | J9: 178 días | K9: mié 5/20/26 | L9: lun 1/4/27
D10: LOTE 20 M-663 ARTICO-A | E10: 181d | F10: 5/29/26 3:00 | G10: 1/18/27 12:00 | I10: LOTE 20 M-663 ARTICO-A | J10: 181 días | K10: mar 6/2/26 | L10: mié 1/20/27
D11: LOTE 21 M-663 CORSAC-A | E11: 181d | F11: 5/29/26 3:00 | G11: 1/18/27 12:00 | I11: LOTE 21 M-663 CORSAC-A | J11: 181 días | K11: mar 6/2/26 | L11: mié 1/20/27
D12: LOTE 22 M-663 CORSAC-B | E12: 174d | F12: 46301.5 | G12: 1/20/27 12:00 | I12: LOTE 22 M-663 CORSAC-B | J12: 174 días | K12: mié 6/10/26 | L12: mié 1/20/27
F16: 46153 | G16: 46042 | H16: 46042 | I16: =+H16-G16 -> 0 | K16: 46153 | L16: 46042
F17: 46153 | G17: 46183 | H17: 46183 | I17: =+H17-G17 -> 0 | K17: 46153 | L17: 46183
F18: 46153 | H18: 46378 | I18: =+H18-G18 -> 46378 | K18: 46153 | L18: 46378
F19: 46162 | G19: 46026 | H19: 46026 | I19: =+H19-G19 -> 0 | K19: 46162 | L19: 46026
F20: 46162 | G20: 46026 | H20: 46026 | I20: =+H20-G20 -> 0 | K20: 46162 | L20: 46026
F21: 46171 | G21: 46040 | H21: 46042 | I21: =+H21-G21 -> 2 | K21: 46175 | L21: 46042
F22: 46171 | G22: 46040 | H22: 46042 | I22: =+H22-G22 -> 2 | K22: 46175 | L22: 46042
F23: 46183 | G23: 46407 | H23: 46407 | I23: =+H23-G23 -> 0 | K23: 46183 | L23: 46407
